[2025-03-17T22:35:11.879+0000] {taskinstance.py:1956} INFO - Dependencies all met for dep_context=non-requeueable deps ti=<TaskInstance: Google_map.load_phase_task manual__2025-03-16T19:25:20.443285+00:00 [queued]>
[2025-03-17T22:35:11.901+0000] {taskinstance.py:1956} INFO - Dependencies all met for dep_context=requeueable deps ti=<TaskInstance: Google_map.load_phase_task manual__2025-03-16T19:25:20.443285+00:00 [queued]>
[2025-03-17T22:35:11.901+0000] {taskinstance.py:2170} INFO - Starting attempt 1 of 2
[2025-03-17T22:35:11.939+0000] {taskinstance.py:2191} INFO - Executing <Task(BashOperator): load_phase_task> on 2025-03-16 19:25:20.443285+00:00
[2025-03-17T22:35:11.945+0000] {standard_task_runner.py:60} INFO - Started process 20329 to run task
[2025-03-17T22:35:11.957+0000] {standard_task_runner.py:87} INFO - Running: ['airflow', 'tasks', 'run', 'Google_map', 'load_phase_task', 'manual__2025-03-16T19:25:20.443285+00:00', '--job-id', '228', '--raw', '--subdir', 'DAGS_FOLDER/google_map_dag_etl.py', '--cfg-path', '/tmp/tmpgi64if4q']
[2025-03-17T22:35:11.973+0000] {standard_task_runner.py:88} INFO - Job 228: Subtask load_phase_task
[2025-03-17T22:35:12.159+0000] {task_command.py:423} INFO - Running <TaskInstance: Google_map.load_phase_task manual__2025-03-16T19:25:20.443285+00:00 [running]> on host DESKTOP-AVAHALM.
[2025-03-17T22:35:12.519+0000] {taskinstance.py:2480} INFO - Exporting env vars: AIRFLOW_CTX_DAG_OWNER='master_m2si' AIRFLOW_CTX_DAG_ID='Google_map' AIRFLOW_CTX_TASK_ID='load_phase_task' AIRFLOW_CTX_EXECUTION_DATE='2025-03-16T19:25:20.443285+00:00' AIRFLOW_CTX_TRY_NUMBER='1' AIRFLOW_CTX_DAG_RUN_ID='manual__2025-03-16T19:25:20.443285+00:00'
[2025-03-17T22:35:12.523+0000] {subprocess.py:63} INFO - Tmp dir root location: /tmp
[2025-03-17T22:35:12.527+0000] {subprocess.py:75} INFO - Running command: ['/usr/bin/bash', '-c', 'cd ~/data_warehouse_project && dbt run --profiles-dir ~/.dbt --models dim_bank dim_branch dim_location dim_sentiment fact_reviews']
[2025-03-17T22:35:12.547+0000] {subprocess.py:86} INFO - Output:
[2025-03-17T22:35:16.396+0000] {subprocess.py:93} INFO - [0m22:35:16  Running with dbt=1.9.0-b2
[2025-03-17T22:35:16.981+0000] {subprocess.py:93} INFO - [0m22:35:16  Registered adapter: postgres=1.8.2
[2025-03-17T22:35:17.833+0000] {subprocess.py:93} INFO - [0m22:35:17  [[33mWARNING[0m]: Configuration paths exist in your dbt_project.yml file which do not apply to any resources.
[2025-03-17T22:35:17.833+0000] {subprocess.py:93} INFO - There are 1 unused configuration paths:
[2025-03-17T22:35:17.834+0000] {subprocess.py:93} INFO - - models.data_warehouse_project.example
[2025-03-17T22:35:18.419+0000] {subprocess.py:93} INFO - [0m22:35:18  Found 6 models, 1 source, 424 macros
[2025-03-17T22:35:18.430+0000] {subprocess.py:93} INFO - [0m22:35:18
[2025-03-17T22:35:18.433+0000] {subprocess.py:93} INFO - [0m22:35:18  Concurrency: 4 threads (target='dev')
[2025-03-17T22:35:18.435+0000] {subprocess.py:93} INFO - [0m22:35:18
[2025-03-17T22:35:18.875+0000] {subprocess.py:93} INFO - [0m22:35:18  1 of 5 START sql table model public_Decisionnelle.dim_bank ..................... [RUN]
[2025-03-17T22:35:18.887+0000] {subprocess.py:93} INFO - [0m22:35:18  2 of 5 START sql table model public_Decisionnelle.dim_branch ................... [RUN]
[2025-03-17T22:35:18.910+0000] {subprocess.py:93} INFO - [0m22:35:18  3 of 5 START sql table model public_Decisionnelle.dim_location ................. [RUN]
[2025-03-17T22:35:18.913+0000] {subprocess.py:93} INFO - [0m22:35:18  4 of 5 START sql table model public_Decisionnelle.dim_sentiment ................ [RUN]
[2025-03-17T22:35:19.562+0000] {subprocess.py:93} INFO - [0m22:35:19  2 of 5 OK created sql table model public_Decisionnelle.dim_branch .............. [[32mSELECT 2[0m in 0.64s]
[2025-03-17T22:35:19.667+0000] {subprocess.py:93} INFO - [0m22:35:19  4 of 5 ERROR creating sql table model public_Decisionnelle.dim_sentiment ....... [[31mERROR[0m in 0.73s]
[2025-03-17T22:35:19.669+0000] {subprocess.py:93} INFO - [0m22:35:19  3 of 5 ERROR creating sql table model public_Decisionnelle.dim_location ........ [[31mERROR[0m in 0.75s]
[2025-03-17T22:35:19.672+0000] {subprocess.py:93} INFO - [0m22:35:19  1 of 5 ERROR creating sql table model public_Decisionnelle.dim_bank ............ [[31mERROR[0m in 0.79s]
[2025-03-17T22:35:19.701+0000] {subprocess.py:93} INFO - [0m22:35:19  5 of 5 SKIP relation public_Decisionnelle.fact_reviews ......................... [[33mSKIP[0m]
[2025-03-17T22:35:19.753+0000] {subprocess.py:93} INFO - [0m22:35:19
[2025-03-17T22:35:19.754+0000] {subprocess.py:93} INFO - [0m22:35:19  Finished running 5 table models in 0 hours 0 minutes and 1.31 seconds (1.31s).
[2025-03-17T22:35:19.980+0000] {subprocess.py:93} INFO - [0m22:35:19
[2025-03-17T22:35:19.982+0000] {subprocess.py:93} INFO - [0m22:35:19  [31mCompleted with 3 errors, 0 partial successs, and 0 warnings:[0m
[2025-03-17T22:35:19.984+0000] {subprocess.py:93} INFO - [0m22:35:19
[2025-03-17T22:35:19.985+0000] {subprocess.py:93} INFO - [0m22:35:19    Database Error in model dim_bank (models/marts/dim_bank.sql)
[2025-03-17T22:35:19.985+0000] {subprocess.py:93} INFO -   relation "dim_bank__dbt_backup" already exists
[2025-03-17T22:35:19.986+0000] {subprocess.py:93} INFO -   compiled code at target/run/data_warehouse_project/models/marts/dim_bank.sql
[2025-03-17T22:35:19.986+0000] {subprocess.py:93} INFO - [0m22:35:19
[2025-03-17T22:35:19.986+0000] {subprocess.py:93} INFO - [0m22:35:19    Database Error in model dim_sentiment (models/marts/dim_sentiment.sql)
[2025-03-17T22:35:19.987+0000] {subprocess.py:93} INFO -   relation "dim_sentiment__dbt_backup" already exists
[2025-03-17T22:35:19.987+0000] {subprocess.py:93} INFO -   compiled code at target/run/data_warehouse_project/models/marts/dim_sentiment.sql
[2025-03-17T22:35:19.987+0000] {subprocess.py:93} INFO - [0m22:35:19
[2025-03-17T22:35:19.988+0000] {subprocess.py:93} INFO - [0m22:35:19    Database Error in model dim_location (models/marts/dim_location.sql)
[2025-03-17T22:35:19.989+0000] {subprocess.py:93} INFO -   relation "dim_location__dbt_backup" already exists
[2025-03-17T22:35:19.989+0000] {subprocess.py:93} INFO -   compiled code at target/run/data_warehouse_project/models/marts/dim_location.sql
[2025-03-17T22:35:19.990+0000] {subprocess.py:93} INFO - [0m22:35:19
[2025-03-17T22:35:19.992+0000] {subprocess.py:93} INFO - [0m22:35:19  Done. PASS=1 WARN=0 ERROR=3 SKIP=1 TOTAL=5
[2025-03-17T22:35:22.061+0000] {subprocess.py:97} INFO - Command exited with return code 1
[2025-03-17T22:35:22.092+0000] {taskinstance.py:2698} ERROR - Task failed with exception
Traceback (most recent call last):
  File "/home/nord/venv/lib/python3.8/site-packages/airflow/models/taskinstance.py", line 433, in _execute_task
    result = execute_callable(context=context, **execute_callable_kwargs)
  File "/home/nord/venv/lib/python3.8/site-packages/airflow/operators/bash.py", line 212, in execute
    raise AirflowException(
airflow.exceptions.AirflowException: Bash command failed. The command returned a non-zero exit code 1.
[2025-03-17T22:35:22.097+0000] {taskinstance.py:1138} INFO - Marking task as UP_FOR_RETRY. dag_id=Google_map, task_id=load_phase_task, execution_date=20250316T192520, start_date=20250317T223511, end_date=20250317T223522
[2025-03-17T22:35:22.121+0000] {standard_task_runner.py:107} ERROR - Failed to execute job 228 for task load_phase_task (Bash command failed. The command returned a non-zero exit code 1.; 20329)
[2025-03-17T22:35:22.136+0000] {local_task_job_runner.py:234} INFO - Task exited with return code 1
[2025-03-17T22:35:22.169+0000] {taskinstance.py:3280} INFO - 0 downstream tasks scheduled from follow-on schedule check
