[2025-03-17T22:30:26.513+0000] {taskinstance.py:1956} INFO - Dependencies all met for dep_context=non-requeueable deps ti=<TaskInstance: Google_map.transform_data_phase_1_task manual__2025-03-16T19:34:18.501436+00:00 [queued]>
[2025-03-17T22:30:26.750+0000] {taskinstance.py:1956} INFO - Dependencies all met for dep_context=requeueable deps ti=<TaskInstance: Google_map.transform_data_phase_1_task manual__2025-03-16T19:34:18.501436+00:00 [queued]>
[2025-03-17T22:30:26.751+0000] {taskinstance.py:2170} INFO - Starting attempt 1 of 2
[2025-03-17T22:30:28.147+0000] {taskinstance.py:2191} INFO - Executing <Task(BashOperator): transform_data_phase_1_task> on 2025-03-16 19:34:18.501436+00:00
[2025-03-17T22:30:28.199+0000] {standard_task_runner.py:60} INFO - Started process 15997 to run task
[2025-03-17T22:30:28.247+0000] {standard_task_runner.py:87} INFO - Running: ['airflow', 'tasks', 'run', 'Google_map', 'transform_data_phase_1_task', 'manual__2025-03-16T19:34:18.501436+00:00', '--job-id', '196', '--raw', '--subdir', 'DAGS_FOLDER/google_map_dag_etl.py', '--cfg-path', '/tmp/tmpj7szqwa5']
[2025-03-17T22:30:28.330+0000] {standard_task_runner.py:88} INFO - Job 196: Subtask transform_data_phase_1_task
[2025-03-17T22:30:31.365+0000] {task_command.py:423} INFO - Running <TaskInstance: Google_map.transform_data_phase_1_task manual__2025-03-16T19:34:18.501436+00:00 [running]> on host DESKTOP-AVAHALM.
[2025-03-17T22:30:35.618+0000] {taskinstance.py:2480} INFO - Exporting env vars: AIRFLOW_CTX_DAG_OWNER='master_m2si' AIRFLOW_CTX_DAG_ID='Google_map' AIRFLOW_CTX_TASK_ID='transform_data_phase_1_task' AIRFLOW_CTX_EXECUTION_DATE='2025-03-16T19:34:18.501436+00:00' AIRFLOW_CTX_TRY_NUMBER='1' AIRFLOW_CTX_DAG_RUN_ID='manual__2025-03-16T19:34:18.501436+00:00'
[2025-03-17T22:30:35.624+0000] {subprocess.py:63} INFO - Tmp dir root location: /tmp
[2025-03-17T22:30:35.625+0000] {subprocess.py:75} INFO - Running command: ['/usr/bin/bash', '-c', 'cd ~/data_warehouse_project && dbt run --profiles-dir ~/.dbt --models cleaned_reviews']
[2025-03-17T22:30:35.709+0000] {subprocess.py:86} INFO - Output:
[2025-03-17T22:30:58.892+0000] {subprocess.py:93} INFO - [0m22:30:58  Running with dbt=1.9.0-b2
[2025-03-17T22:31:04.765+0000] {subprocess.py:93} INFO - [0m22:31:04  Registered adapter: postgres=1.8.2
[2025-03-17T22:31:09.319+0000] {subprocess.py:93} INFO - [0m22:31:09  [[33mWARNING[0m]: Configuration paths exist in your dbt_project.yml file which do not apply to any resources.
[2025-03-17T22:31:09.319+0000] {subprocess.py:93} INFO - There are 1 unused configuration paths:
[2025-03-17T22:31:09.320+0000] {subprocess.py:93} INFO - - models.data_warehouse_project.example
[2025-03-17T22:31:12.648+0000] {subprocess.py:93} INFO - [0m22:31:12  Found 6 models, 1 source, 424 macros
[2025-03-17T22:31:12.662+0000] {subprocess.py:93} INFO - [0m22:31:12
[2025-03-17T22:31:12.680+0000] {subprocess.py:93} INFO - [0m22:31:12  Concurrency: 4 threads (target='dev')
[2025-03-17T22:31:12.682+0000] {subprocess.py:93} INFO - [0m22:31:12
[2025-03-17T22:31:15.152+0000] {local_task_job_runner.py:302} WARNING - State of this instance has been externally set to restarting. Terminating instance.
[2025-03-17T22:31:15.206+0000] {process_utils.py:131} INFO - Sending 15 to group 15997. PIDs of all processes in the group: [16161, 16518, 15997]
[2025-03-17T22:31:15.207+0000] {process_utils.py:86} INFO - Sending the signal 15 to group 15997
[2025-03-17T22:31:15.207+0000] {taskinstance.py:2450} ERROR - Received SIGTERM. Terminating subprocesses.
[2025-03-17T22:31:15.208+0000] {subprocess.py:104} INFO - Sending SIGTERM signal to process group
[2025-03-17T22:31:15.605+0000] {process_utils.py:79} INFO - Process psutil.Process(pid=16518, status='terminated', started='22:31:04') (16518) terminated with exit code None
[2025-03-17T22:31:15.993+0000] {taskinstance.py:2698} ERROR - Task failed with exception
Traceback (most recent call last):
  File "/home/nord/venv/lib/python3.8/site-packages/airflow/models/taskinstance.py", line 433, in _execute_task
    result = execute_callable(context=context, **execute_callable_kwargs)
  File "/home/nord/venv/lib/python3.8/site-packages/airflow/operators/bash.py", line 203, in execute
    result = self.subprocess_hook.run_command(
  File "/home/nord/venv/lib/python3.8/site-packages/airflow/hooks/subprocess.py", line 91, in run_command
    for raw_line in iter(self.sub_process.stdout.readline, b""):
  File "/home/nord/venv/lib/python3.8/site-packages/airflow/models/taskinstance.py", line 2452, in signal_handler
    raise AirflowException("Task received SIGTERM signal")
airflow.exceptions.AirflowException: Task received SIGTERM signal
[2025-03-17T22:31:16.016+0000] {taskinstance.py:1138} INFO - Marking task as UP_FOR_RETRY. dag_id=Google_map, task_id=transform_data_phase_1_task, execution_date=20250316T193418, start_date=20250317T223026, end_date=20250317T223116
[2025-03-17T22:31:17.790+0000] {standard_task_runner.py:107} ERROR - Failed to execute job 196 for task transform_data_phase_1_task (Task received SIGTERM signal; 15997)
[2025-03-17T22:31:17.846+0000] {process_utils.py:79} INFO - Process psutil.Process(pid=16161, status='terminated', started='22:30:35') (16161) terminated with exit code None
[2025-03-17T22:31:17.847+0000] {process_utils.py:79} INFO - Process psutil.Process(pid=15997, status='terminated', exitcode=1, started='22:30:27') (15997) terminated with exit code 1
