[2025-03-16T17:38:40.450+0000] {taskinstance.py:1956} INFO - Dependencies all met for dep_context=non-requeueable deps ti=<TaskInstance: Google_map.transform_phase_2_task manual__2025-03-16T16:15:39.596689+00:00 [queued]>
[2025-03-16T17:38:40.464+0000] {taskinstance.py:1956} INFO - Dependencies all met for dep_context=requeueable deps ti=<TaskInstance: Google_map.transform_phase_2_task manual__2025-03-16T16:15:39.596689+00:00 [queued]>
[2025-03-16T17:38:40.464+0000] {taskinstance.py:2170} INFO - Starting attempt 11 of 12
[2025-03-16T17:38:40.490+0000] {taskinstance.py:2191} INFO - Executing <Task(PythonOperator): transform_phase_2_task> on 2025-03-16 16:15:39.596689+00:00
[2025-03-16T17:38:40.496+0000] {standard_task_runner.py:60} INFO - Started process 144187 to run task
[2025-03-16T17:38:40.503+0000] {standard_task_runner.py:87} INFO - Running: ['airflow', 'tasks', 'run', 'Google_map', 'transform_phase_2_task', 'manual__2025-03-16T16:15:39.596689+00:00', '--job-id', '133', '--raw', '--subdir', 'DAGS_FOLDER/google_map_dag_etl.py', '--cfg-path', '/tmp/tmp44msf0h6']
[2025-03-16T17:38:40.506+0000] {standard_task_runner.py:88} INFO - Job 133: Subtask transform_phase_2_task
[2025-03-16T17:38:40.625+0000] {task_command.py:423} INFO - Running <TaskInstance: Google_map.transform_phase_2_task manual__2025-03-16T16:15:39.596689+00:00 [running]> on host DESKTOP-AVAHALM.
[2025-03-16T17:38:40.840+0000] {taskinstance.py:2480} INFO - Exporting env vars: AIRFLOW_CTX_DAG_OWNER='master_m2si' AIRFLOW_CTX_DAG_ID='Google_map' AIRFLOW_CTX_TASK_ID='transform_phase_2_task' AIRFLOW_CTX_EXECUTION_DATE='2025-03-16T16:15:39.596689+00:00' AIRFLOW_CTX_TRY_NUMBER='11' AIRFLOW_CTX_DAG_RUN_ID='manual__2025-03-16T16:15:39.596689+00:00'
[2025-03-16T17:38:52.375+0000] {taskinstance.py:2698} ERROR - Task failed with exception
Traceback (most recent call last):
  File "/home/nord/venv/lib/python3.8/site-packages/airflow/models/taskinstance.py", line 433, in _execute_task
    result = execute_callable(context=context, **execute_callable_kwargs)
  File "/home/nord/venv/lib/python3.8/site-packages/airflow/operators/python.py", line 199, in execute
    return_value = self.execute_callable()
  File "/home/nord/venv/lib/python3.8/site-packages/airflow/operators/python.py", line 216, in execute_callable
    return self.python_callable(*self.op_args, **self.op_kwargs)
  File "/home/nord/airflow/dags/google_map_dag_etl.py", line 51, in <lambda>
    python_callable=lambda: __import__('transform_phase_2').main()
  File "/home/nord/airflow/dags/transform_phase_2.py", line 68, in main
    df_filtered['topics'] = ['; '.join(topic) for topic in topics]  # Join topic words as a string
  File "/home/nord/venv/lib/python3.8/site-packages/pandas/core/frame.py", line 3950, in __setitem__
    self._set_item(key, value)
  File "/home/nord/venv/lib/python3.8/site-packages/pandas/core/frame.py", line 4143, in _set_item
    value = self._sanitize_column(value)
  File "/home/nord/venv/lib/python3.8/site-packages/pandas/core/frame.py", line 4870, in _sanitize_column
    com.require_length_match(value, self.index)
  File "/home/nord/venv/lib/python3.8/site-packages/pandas/core/common.py", line 576, in require_length_match
    raise ValueError(
ValueError: Length of values (5) does not match length of index (1)
[2025-03-16T17:38:52.397+0000] {taskinstance.py:1138} INFO - Marking task as UP_FOR_RETRY. dag_id=Google_map, task_id=transform_phase_2_task, execution_date=20250316T161539, start_date=20250316T173840, end_date=20250316T173852
[2025-03-16T17:38:52.417+0000] {standard_task_runner.py:107} ERROR - Failed to execute job 133 for task transform_phase_2_task (Length of values (5) does not match length of index (1); 144187)
[2025-03-16T17:38:52.562+0000] {local_task_job_runner.py:234} INFO - Task exited with return code 1
[2025-03-16T17:38:52.635+0000] {taskinstance.py:3280} INFO - 0 downstream tasks scheduled from follow-on schedule check
