[2025-03-16T17:26:46.272+0000] {taskinstance.py:1956} INFO - Dependencies all met for dep_context=non-requeueable deps ti=<TaskInstance: Google_map.transform_phase_2_task manual__2025-03-16T16:15:39.596689+00:00 [queued]>
[2025-03-16T17:26:46.309+0000] {taskinstance.py:1956} INFO - Dependencies all met for dep_context=requeueable deps ti=<TaskInstance: Google_map.transform_phase_2_task manual__2025-03-16T16:15:39.596689+00:00 [queued]>
[2025-03-16T17:26:46.310+0000] {taskinstance.py:2170} INFO - Starting attempt 8 of 9
[2025-03-16T17:26:46.378+0000] {taskinstance.py:2191} INFO - Executing <Task(PythonOperator): transform_phase_2_task> on 2025-03-16 16:15:39.596689+00:00
[2025-03-16T17:26:46.386+0000] {standard_task_runner.py:60} INFO - Started process 136382 to run task
[2025-03-16T17:26:46.397+0000] {standard_task_runner.py:87} INFO - Running: ['airflow', 'tasks', 'run', 'Google_map', 'transform_phase_2_task', 'manual__2025-03-16T16:15:39.596689+00:00', '--job-id', '130', '--raw', '--subdir', 'DAGS_FOLDER/google_map_dag_etl.py', '--cfg-path', '/tmp/tmp8qo3i_uk']
[2025-03-16T17:26:46.413+0000] {standard_task_runner.py:88} INFO - Job 130: Subtask transform_phase_2_task
[2025-03-16T17:26:46.686+0000] {task_command.py:423} INFO - Running <TaskInstance: Google_map.transform_phase_2_task manual__2025-03-16T16:15:39.596689+00:00 [running]> on host DESKTOP-AVAHALM.
[2025-03-16T17:26:47.326+0000] {taskinstance.py:2480} INFO - Exporting env vars: AIRFLOW_CTX_DAG_OWNER='master_m2si' AIRFLOW_CTX_DAG_ID='Google_map' AIRFLOW_CTX_TASK_ID='transform_phase_2_task' AIRFLOW_CTX_EXECUTION_DATE='2025-03-16T16:15:39.596689+00:00' AIRFLOW_CTX_TRY_NUMBER='8' AIRFLOW_CTX_DAG_RUN_ID='manual__2025-03-16T16:15:39.596689+00:00'
[2025-03-16T17:33:57.945+0000] {taskinstance.py:2698} ERROR - Task failed with exception
Traceback (most recent call last):
  File "/home/nord/venv/lib/python3.8/site-packages/sqlalchemy/engine/base.py", line 3371, in _wrap_pool_connect
    return fn()
  File "/home/nord/venv/lib/python3.8/site-packages/sqlalchemy/pool/base.py", line 327, in connect
    return _ConnectionFairy._checkout(self)
  File "/home/nord/venv/lib/python3.8/site-packages/sqlalchemy/pool/base.py", line 894, in _checkout
    fairy = _ConnectionRecord.checkout(pool)
  File "/home/nord/venv/lib/python3.8/site-packages/sqlalchemy/pool/base.py", line 493, in checkout
    rec = pool._do_get()
  File "/home/nord/venv/lib/python3.8/site-packages/sqlalchemy/pool/impl.py", line 146, in _do_get
    self._dec_overflow()
  File "/home/nord/venv/lib/python3.8/site-packages/sqlalchemy/util/langhelpers.py", line 70, in __exit__
    compat.raise_(
  File "/home/nord/venv/lib/python3.8/site-packages/sqlalchemy/util/compat.py", line 211, in raise_
    raise exception
  File "/home/nord/venv/lib/python3.8/site-packages/sqlalchemy/pool/impl.py", line 143, in _do_get
    return self._create_connection()
  File "/home/nord/venv/lib/python3.8/site-packages/sqlalchemy/pool/base.py", line 273, in _create_connection
    return _ConnectionRecord(self)
  File "/home/nord/venv/lib/python3.8/site-packages/sqlalchemy/pool/base.py", line 388, in __init__
    self.__connect()
  File "/home/nord/venv/lib/python3.8/site-packages/sqlalchemy/pool/base.py", line 691, in __connect
    pool.logger.debug("Error on connect(): %s", e)
  File "/home/nord/venv/lib/python3.8/site-packages/sqlalchemy/util/langhelpers.py", line 70, in __exit__
    compat.raise_(
  File "/home/nord/venv/lib/python3.8/site-packages/sqlalchemy/util/compat.py", line 211, in raise_
    raise exception
  File "/home/nord/venv/lib/python3.8/site-packages/sqlalchemy/pool/base.py", line 686, in __connect
    self.dbapi_connection = connection = pool._invoke_creator(self)
  File "/home/nord/venv/lib/python3.8/site-packages/sqlalchemy/engine/create.py", line 574, in connect
    return dialect.connect(*cargs, **cparams)
  File "/home/nord/venv/lib/python3.8/site-packages/sqlalchemy/engine/default.py", line 598, in connect
    return self.dbapi.connect(*cargs, **cparams)
  File "/home/nord/venv/lib/python3.8/site-packages/psycopg2/__init__.py", line 122, in connect
    conn = _connect(dsn, connection_factory=connection_factory, **kwasync)
psycopg2.OperationalError: connection to server at "localhost" (127.0.0.1), port 5432 failed: FATAL:  password authentication failed for user "username"
connection to server at "localhost" (127.0.0.1), port 5432 failed: FATAL:  password authentication failed for user "username"


The above exception was the direct cause of the following exception:

Traceback (most recent call last):
  File "/home/nord/venv/lib/python3.8/site-packages/airflow/models/taskinstance.py", line 433, in _execute_task
    result = execute_callable(context=context, **execute_callable_kwargs)
  File "/home/nord/venv/lib/python3.8/site-packages/airflow/operators/python.py", line 199, in execute
    return_value = self.execute_callable()
  File "/home/nord/venv/lib/python3.8/site-packages/airflow/operators/python.py", line 216, in execute_callable
    return self.python_callable(*self.op_args, **self.op_kwargs)
  File "/home/nord/airflow/dags/google_map_dag_etl.py", line 51, in <lambda>
    python_callable=lambda: __import__('transform_phase_2').main()
  File "/home/nord/airflow/dags/transform_phase_2.py", line 18, in <module>
    connection = db_engine.connect()
  File "/home/nord/venv/lib/python3.8/site-packages/sqlalchemy/engine/base.py", line 3325, in connect
    return self._connection_cls(self, close_with_result=close_with_result)
  File "/home/nord/venv/lib/python3.8/site-packages/sqlalchemy/engine/base.py", line 96, in __init__
    else engine.raw_connection()
  File "/home/nord/venv/lib/python3.8/site-packages/sqlalchemy/engine/base.py", line 3404, in raw_connection
    return self._wrap_pool_connect(self.pool.connect, _connection)
  File "/home/nord/venv/lib/python3.8/site-packages/sqlalchemy/engine/base.py", line 3374, in _wrap_pool_connect
    Connection._handle_dbapi_exception_noconnection(
  File "/home/nord/venv/lib/python3.8/site-packages/sqlalchemy/engine/base.py", line 2208, in _handle_dbapi_exception_noconnection
    util.raise_(
  File "/home/nord/venv/lib/python3.8/site-packages/sqlalchemy/util/compat.py", line 211, in raise_
    raise exception
  File "/home/nord/venv/lib/python3.8/site-packages/sqlalchemy/engine/base.py", line 3371, in _wrap_pool_connect
    return fn()
  File "/home/nord/venv/lib/python3.8/site-packages/sqlalchemy/pool/base.py", line 327, in connect
    return _ConnectionFairy._checkout(self)
  File "/home/nord/venv/lib/python3.8/site-packages/sqlalchemy/pool/base.py", line 894, in _checkout
    fairy = _ConnectionRecord.checkout(pool)
  File "/home/nord/venv/lib/python3.8/site-packages/sqlalchemy/pool/base.py", line 493, in checkout
    rec = pool._do_get()
  File "/home/nord/venv/lib/python3.8/site-packages/sqlalchemy/pool/impl.py", line 146, in _do_get
    self._dec_overflow()
  File "/home/nord/venv/lib/python3.8/site-packages/sqlalchemy/util/langhelpers.py", line 70, in __exit__
    compat.raise_(
  File "/home/nord/venv/lib/python3.8/site-packages/sqlalchemy/util/compat.py", line 211, in raise_
    raise exception
  File "/home/nord/venv/lib/python3.8/site-packages/sqlalchemy/pool/impl.py", line 143, in _do_get
    return self._create_connection()
  File "/home/nord/venv/lib/python3.8/site-packages/sqlalchemy/pool/base.py", line 273, in _create_connection
    return _ConnectionRecord(self)
  File "/home/nord/venv/lib/python3.8/site-packages/sqlalchemy/pool/base.py", line 388, in __init__
    self.__connect()
  File "/home/nord/venv/lib/python3.8/site-packages/sqlalchemy/pool/base.py", line 691, in __connect
    pool.logger.debug("Error on connect(): %s", e)
  File "/home/nord/venv/lib/python3.8/site-packages/sqlalchemy/util/langhelpers.py", line 70, in __exit__
    compat.raise_(
  File "/home/nord/venv/lib/python3.8/site-packages/sqlalchemy/util/compat.py", line 211, in raise_
    raise exception
  File "/home/nord/venv/lib/python3.8/site-packages/sqlalchemy/pool/base.py", line 686, in __connect
    self.dbapi_connection = connection = pool._invoke_creator(self)
  File "/home/nord/venv/lib/python3.8/site-packages/sqlalchemy/engine/create.py", line 574, in connect
    return dialect.connect(*cargs, **cparams)
  File "/home/nord/venv/lib/python3.8/site-packages/sqlalchemy/engine/default.py", line 598, in connect
    return self.dbapi.connect(*cargs, **cparams)
  File "/home/nord/venv/lib/python3.8/site-packages/psycopg2/__init__.py", line 122, in connect
    conn = _connect(dsn, connection_factory=connection_factory, **kwasync)
sqlalchemy.exc.OperationalError: (psycopg2.OperationalError) connection to server at "localhost" (127.0.0.1), port 5432 failed: FATAL:  password authentication failed for user "username"
connection to server at "localhost" (127.0.0.1), port 5432 failed: FATAL:  password authentication failed for user "username"

(Background on this error at: https://sqlalche.me/e/14/e3q8)
[2025-03-16T17:33:58.019+0000] {taskinstance.py:1138} INFO - Marking task as UP_FOR_RETRY. dag_id=Google_map, task_id=transform_phase_2_task, execution_date=20250316T161539, start_date=20250316T172646, end_date=20250316T173358
[2025-03-16T17:33:58.053+0000] {standard_task_runner.py:107} ERROR - Failed to execute job 130 for task transform_phase_2_task ((psycopg2.OperationalError) connection to server at "localhost" (127.0.0.1), port 5432 failed: FATAL:  password authentication failed for user "username"
connection to server at "localhost" (127.0.0.1), port 5432 failed: FATAL:  password authentication failed for user "username"

(Background on this error at: https://sqlalche.me/e/14/e3q8); 136382)
[2025-03-16T17:33:58.140+0000] {local_task_job_runner.py:234} INFO - Task exited with return code 1
[2025-03-16T17:33:58.176+0000] {taskinstance.py:3280} INFO - 0 downstream tasks scheduled from follow-on schedule check
