[2025-03-17T22:30:27.021+0000] {taskinstance.py:1956} INFO - Dependencies all met for dep_context=non-requeueable deps ti=<TaskInstance: Google_map.transform_data_phase_1_task manual__2025-03-16T19:25:20.443285+00:00 [queued]>
[2025-03-17T22:30:27.127+0000] {taskinstance.py:1956} INFO - Dependencies all met for dep_context=requeueable deps ti=<TaskInstance: Google_map.transform_data_phase_1_task manual__2025-03-16T19:25:20.443285+00:00 [queued]>
[2025-03-17T22:30:27.135+0000] {taskinstance.py:2170} INFO - Starting attempt 1 of 2
[2025-03-17T22:30:27.674+0000] {taskinstance.py:2191} INFO - Executing <Task(BashOperator): transform_data_phase_1_task> on 2025-03-16 19:25:20.443285+00:00
[2025-03-17T22:30:27.733+0000] {standard_task_runner.py:60} INFO - Started process 15980 to run task
[2025-03-17T22:30:27.785+0000] {standard_task_runner.py:87} INFO - Running: ['airflow', 'tasks', 'run', 'Google_map', 'transform_data_phase_1_task', 'manual__2025-03-16T19:25:20.443285+00:00', '--job-id', '200', '--raw', '--subdir', 'DAGS_FOLDER/google_map_dag_etl.py', '--cfg-path', '/tmp/tmpna79lq0c']
[2025-03-17T22:30:27.801+0000] {standard_task_runner.py:88} INFO - Job 200: Subtask transform_data_phase_1_task
[2025-03-17T22:30:30.126+0000] {task_command.py:423} INFO - Running <TaskInstance: Google_map.transform_data_phase_1_task manual__2025-03-16T19:25:20.443285+00:00 [running]> on host DESKTOP-AVAHALM.
[2025-03-17T22:30:34.488+0000] {taskinstance.py:2480} INFO - Exporting env vars: AIRFLOW_CTX_DAG_OWNER='master_m2si' AIRFLOW_CTX_DAG_ID='Google_map' AIRFLOW_CTX_TASK_ID='transform_data_phase_1_task' AIRFLOW_CTX_EXECUTION_DATE='2025-03-16T19:25:20.443285+00:00' AIRFLOW_CTX_TRY_NUMBER='1' AIRFLOW_CTX_DAG_RUN_ID='manual__2025-03-16T19:25:20.443285+00:00'
[2025-03-17T22:30:34.491+0000] {subprocess.py:63} INFO - Tmp dir root location: /tmp
[2025-03-17T22:30:34.501+0000] {subprocess.py:75} INFO - Running command: ['/usr/bin/bash', '-c', 'cd ~/data_warehouse_project && dbt run --profiles-dir ~/.dbt --models cleaned_reviews']
[2025-03-17T22:30:34.534+0000] {subprocess.py:86} INFO - Output:
[2025-03-17T22:30:56.844+0000] {subprocess.py:93} INFO - [0m22:30:56  Running with dbt=1.9.0-b2
[2025-03-17T22:31:03.621+0000] {subprocess.py:93} INFO - [0m22:31:03  Registered adapter: postgres=1.8.2
[2025-03-17T22:31:07.897+0000] {subprocess.py:93} INFO - [0m22:31:07  [[33mWARNING[0m]: Configuration paths exist in your dbt_project.yml file which do not apply to any resources.
[2025-03-17T22:31:07.898+0000] {subprocess.py:93} INFO - There are 1 unused configuration paths:
[2025-03-17T22:31:07.900+0000] {subprocess.py:93} INFO - - models.data_warehouse_project.example
[2025-03-17T22:31:11.050+0000] {subprocess.py:93} INFO - [0m22:31:11  Found 6 models, 1 source, 424 macros
[2025-03-17T22:31:11.074+0000] {subprocess.py:93} INFO - [0m22:31:11
[2025-03-17T22:31:11.092+0000] {subprocess.py:93} INFO - [0m22:31:11  Concurrency: 4 threads (target='dev')
[2025-03-17T22:31:11.094+0000] {subprocess.py:93} INFO - [0m22:31:11
[2025-03-17T22:31:15.799+0000] {subprocess.py:93} INFO - [0m22:31:15  1 of 1 START sql table model public.cleaned_reviews ............................ [RUN]
[2025-03-17T22:31:18.270+0000] {subprocess.py:93} INFO - [0m22:31:18  1 of 1 ERROR creating sql table model public.cleaned_reviews ................... [[31mERROR[0m in 2.42s]
[2025-03-17T22:31:18.570+0000] {subprocess.py:93} INFO - [0m22:31:18
[2025-03-17T22:31:18.633+0000] {subprocess.py:93} INFO - [0m22:31:18  Finished running 1 table model in 0 hours 0 minutes and 7.47 seconds (7.47s).
[2025-03-17T22:31:19.392+0000] {subprocess.py:93} INFO - [0m22:31:19
[2025-03-17T22:31:19.406+0000] {subprocess.py:93} INFO - [0m22:31:19  [31mCompleted with 1 error, 0 partial successs, and 0 warnings:[0m
[2025-03-17T22:31:19.408+0000] {subprocess.py:93} INFO - [0m22:31:19
[2025-03-17T22:31:19.410+0000] {subprocess.py:93} INFO - [0m22:31:19    Database Error in model cleaned_reviews (models/cleaned_reviews.sql)
[2025-03-17T22:31:19.411+0000] {subprocess.py:93} INFO -   relation "cleaned_reviews__dbt_backup" already exists
[2025-03-17T22:31:19.411+0000] {subprocess.py:93} INFO -   compiled code at target/run/data_warehouse_project/models/cleaned_reviews.sql
[2025-03-17T22:31:19.426+0000] {subprocess.py:93} INFO - [0m22:31:19
[2025-03-17T22:31:19.434+0000] {subprocess.py:93} INFO - [0m22:31:19  Done. PASS=0 WARN=0 ERROR=1 SKIP=0 TOTAL=1
[2025-03-17T22:31:23.864+0000] {subprocess.py:97} INFO - Command exited with return code 1
[2025-03-17T22:31:24.332+0000] {taskinstance.py:2698} ERROR - Task failed with exception
Traceback (most recent call last):
  File "/home/nord/venv/lib/python3.8/site-packages/airflow/models/taskinstance.py", line 433, in _execute_task
    result = execute_callable(context=context, **execute_callable_kwargs)
  File "/home/nord/venv/lib/python3.8/site-packages/airflow/operators/bash.py", line 212, in execute
    raise AirflowException(
airflow.exceptions.AirflowException: Bash command failed. The command returned a non-zero exit code 1.
[2025-03-17T22:31:24.351+0000] {taskinstance.py:1138} INFO - Marking task as UP_FOR_RETRY. dag_id=Google_map, task_id=transform_data_phase_1_task, execution_date=20250316T192520, start_date=20250317T223027, end_date=20250317T223124
[2025-03-17T22:31:25.117+0000] {standard_task_runner.py:107} ERROR - Failed to execute job 200 for task transform_data_phase_1_task (Bash command failed. The command returned a non-zero exit code 1.; 15980)
[2025-03-17T22:31:25.215+0000] {local_task_job_runner.py:234} INFO - Task exited with return code 1
[2025-03-17T22:31:25.779+0000] {taskinstance.py:3280} INFO - 0 downstream tasks scheduled from follow-on schedule check
