[2025-03-15T22:01:33.299+0000] {taskinstance.py:1956} INFO - Dependencies all met for dep_context=non-requeueable deps ti=<TaskInstance: Google_map.insert_data_task manual__2025-03-15T22:01:29.743852+00:00 [queued]>
[2025-03-15T22:01:33.334+0000] {taskinstance.py:1956} INFO - Dependencies all met for dep_context=requeueable deps ti=<TaskInstance: Google_map.insert_data_task manual__2025-03-15T22:01:29.743852+00:00 [queued]>
[2025-03-15T22:01:33.334+0000] {taskinstance.py:2170} INFO - Starting attempt 1 of 2
[2025-03-15T22:01:33.425+0000] {taskinstance.py:2191} INFO - Executing <Task(PythonOperator): insert_data_task> on 2025-03-15 22:01:29.743852+00:00
[2025-03-15T22:01:33.436+0000] {standard_task_runner.py:60} INFO - Started process 167280 to run task
[2025-03-15T22:01:33.467+0000] {standard_task_runner.py:87} INFO - Running: ['airflow', 'tasks', 'run', 'Google_map', 'insert_data_task', 'manual__2025-03-15T22:01:29.743852+00:00', '--job-id', '91', '--raw', '--subdir', 'DAGS_FOLDER/google_map_dag_etl.py', '--cfg-path', '/tmp/tmp5x2e1t1u']
[2025-03-15T22:01:33.486+0000] {standard_task_runner.py:88} INFO - Job 91: Subtask insert_data_task
[2025-03-15T22:01:34.033+0000] {task_command.py:423} INFO - Running <TaskInstance: Google_map.insert_data_task manual__2025-03-15T22:01:29.743852+00:00 [running]> on host DESKTOP-AVAHALM.
[2025-03-15T22:01:34.946+0000] {taskinstance.py:2480} INFO - Exporting env vars: AIRFLOW_CTX_DAG_OWNER='master_m2si' AIRFLOW_CTX_DAG_ID='Google_map' AIRFLOW_CTX_TASK_ID='insert_data_task' AIRFLOW_CTX_EXECUTION_DATE='2025-03-15T22:01:29.743852+00:00' AIRFLOW_CTX_TRY_NUMBER='1' AIRFLOW_CTX_DAG_RUN_ID='manual__2025-03-15T22:01:29.743852+00:00'
[2025-03-15T22:01:34.957+0000] {taskinstance.py:2698} ERROR - Task failed with exception
Traceback (most recent call last):
  File "/home/nord/venv/lib/python3.8/site-packages/airflow/models/taskinstance.py", line 433, in _execute_task
    result = execute_callable(context=context, **execute_callable_kwargs)
  File "/home/nord/venv/lib/python3.8/site-packages/airflow/operators/python.py", line 199, in execute
    return_value = self.execute_callable()
  File "/home/nord/venv/lib/python3.8/site-packages/airflow/operators/python.py", line 216, in execute_callable
    return self.python_callable(*self.op_args, **self.op_kwargs)
  File "/home/nord/airflow/dags/google_map_dag_etl.py", line 41, in <lambda>
    python_callable=lambda: __import__('scripts.insert_script').main()
AttributeError: module 'scripts' has no attribute 'main'
[2025-03-15T22:01:35.050+0000] {taskinstance.py:1138} INFO - Marking task as UP_FOR_RETRY. dag_id=Google_map, task_id=insert_data_task, execution_date=20250315T220129, start_date=20250315T220133, end_date=20250315T220135
[2025-03-15T22:01:35.100+0000] {standard_task_runner.py:107} ERROR - Failed to execute job 91 for task insert_data_task (module 'scripts' has no attribute 'main'; 167280)
[2025-03-15T22:01:35.153+0000] {local_task_job_runner.py:234} INFO - Task exited with return code 1
[2025-03-15T22:01:35.304+0000] {taskinstance.py:3280} INFO - 0 downstream tasks scheduled from follow-on schedule check
