[2025-03-15T22:25:50.994+0000] {taskinstance.py:1956} INFO - Dependencies all met for dep_context=non-requeueable deps ti=<TaskInstance: Google_map.extract_data_task manual__2025-03-15T22:01:29.743852+00:00 [queued]>
[2025-03-15T22:25:51.009+0000] {taskinstance.py:1956} INFO - Dependencies all met for dep_context=requeueable deps ti=<TaskInstance: Google_map.extract_data_task manual__2025-03-15T22:01:29.743852+00:00 [queued]>
[2025-03-15T22:25:51.011+0000] {taskinstance.py:2170} INFO - Starting attempt 4 of 4
[2025-03-15T22:25:51.044+0000] {taskinstance.py:2191} INFO - Executing <Task(PythonOperator): extract_data_task> on 2025-03-15 22:01:29.743852+00:00
[2025-03-15T22:25:51.050+0000] {standard_task_runner.py:60} INFO - Started process 185274 to run task
[2025-03-15T22:25:51.057+0000] {standard_task_runner.py:87} INFO - Running: ['airflow', 'tasks', 'run', 'Google_map', 'extract_data_task', 'manual__2025-03-15T22:01:29.743852+00:00', '--job-id', '94', '--raw', '--subdir', 'DAGS_FOLDER/google_map_dag_etl.py', '--cfg-path', '/tmp/tmpok_v2ldh']
[2025-03-15T22:25:51.063+0000] {standard_task_runner.py:88} INFO - Job 94: Subtask extract_data_task
[2025-03-15T22:25:51.189+0000] {task_command.py:423} INFO - Running <TaskInstance: Google_map.extract_data_task manual__2025-03-15T22:01:29.743852+00:00 [running]> on host DESKTOP-AVAHALM.
[2025-03-15T22:25:51.556+0000] {taskinstance.py:2480} INFO - Exporting env vars: AIRFLOW_CTX_DAG_OWNER='master_m2si' AIRFLOW_CTX_DAG_ID='Google_map' AIRFLOW_CTX_TASK_ID='extract_data_task' AIRFLOW_CTX_EXECUTION_DATE='2025-03-15T22:01:29.743852+00:00' AIRFLOW_CTX_TRY_NUMBER='4' AIRFLOW_CTX_DAG_RUN_ID='manual__2025-03-15T22:01:29.743852+00:00'
[2025-03-15T22:25:51.561+0000] {taskinstance.py:2698} ERROR - Task failed with exception
Traceback (most recent call last):
  File "/home/nord/venv/lib/python3.8/site-packages/airflow/models/taskinstance.py", line 433, in _execute_task
    result = execute_callable(context=context, **execute_callable_kwargs)
  File "/home/nord/venv/lib/python3.8/site-packages/airflow/operators/python.py", line 199, in execute
    return_value = self.execute_callable()
  File "/home/nord/venv/lib/python3.8/site-packages/airflow/operators/python.py", line 216, in execute_callable
    return self.python_callable(*self.op_args, **self.op_kwargs)
  File "/home/nord/airflow/dags/google_map_dag_etl.py", line 37, in <lambda>
    python_callable=lambda: __import__('mini_scraping').main()
ModuleNotFoundError: No module named 'mini_scraping'
[2025-03-15T22:25:51.608+0000] {taskinstance.py:1138} INFO - Marking task as FAILED. dag_id=Google_map, task_id=extract_data_task, execution_date=20250315T220129, start_date=20250315T222550, end_date=20250315T222551
[2025-03-15T22:25:51.640+0000] {standard_task_runner.py:107} ERROR - Failed to execute job 94 for task extract_data_task (No module named 'mini_scraping'; 185274)
[2025-03-15T22:25:51.656+0000] {local_task_job_runner.py:234} INFO - Task exited with return code 1
[2025-03-15T22:25:51.711+0000] {taskinstance.py:3280} INFO - 0 downstream tasks scheduled from follow-on schedule check
