[2025-03-21T16:40:15.753+0000] {taskinstance.py:1956} INFO - Dependencies all met for dep_context=non-requeueable deps ti=<TaskInstance: Google_map.extract_data_task manual__2025-03-21T16:40:09.876807+00:00 [queued]>
[2025-03-21T16:40:15.784+0000] {taskinstance.py:1956} INFO - Dependencies all met for dep_context=requeueable deps ti=<TaskInstance: Google_map.extract_data_task manual__2025-03-21T16:40:09.876807+00:00 [queued]>
[2025-03-21T16:40:15.791+0000] {taskinstance.py:2170} INFO - Starting attempt 1 of 2
[2025-03-21T16:40:15.842+0000] {taskinstance.py:2191} INFO - Executing <Task(PythonOperator): extract_data_task> on 2025-03-21 16:40:09.876807+00:00
[2025-03-21T16:40:15.852+0000] {standard_task_runner.py:60} INFO - Started process 4541 to run task
[2025-03-21T16:40:15.867+0000] {standard_task_runner.py:87} INFO - Running: ['airflow', 'tasks', 'run', 'Google_map', 'extract_data_task', 'manual__2025-03-21T16:40:09.876807+00:00', '--job-id', '274', '--raw', '--subdir', 'DAGS_FOLDER/google_map_dag_etl.py', '--cfg-path', '/tmp/tmpqb6vt18l']
[2025-03-21T16:40:15.878+0000] {standard_task_runner.py:88} INFO - Job 274: Subtask extract_data_task
[2025-03-21T16:40:16.080+0000] {task_command.py:423} INFO - Running <TaskInstance: Google_map.extract_data_task manual__2025-03-21T16:40:09.876807+00:00 [running]> on host DESKTOP-AVAHALM.
[2025-03-21T16:40:16.532+0000] {taskinstance.py:2480} INFO - Exporting env vars: AIRFLOW_CTX_DAG_OWNER='master_m2si' AIRFLOW_CTX_DAG_ID='Google_map' AIRFLOW_CTX_TASK_ID='extract_data_task' AIRFLOW_CTX_EXECUTION_DATE='2025-03-21T16:40:09.876807+00:00' AIRFLOW_CTX_TRY_NUMBER='1' AIRFLOW_CTX_DAG_RUN_ID='manual__2025-03-21T16:40:09.876807+00:00'
[2025-03-21T16:40:17.973+0000] {logger.py:11} INFO - ====== WebDriver manager ======
[2025-03-21T16:40:18.510+0000] {logger.py:11} INFO - Get LATEST chromedriver version for google-chrome
[2025-03-21T16:40:33.216+0000] {logger.py:11} INFO - Get LATEST chromedriver version for google-chrome
[2025-03-21T16:40:36.966+0000] {logger.py:11} INFO - Get LATEST chromedriver version for google-chrome
[2025-03-21T16:40:45.649+0000] {logger.py:11} INFO - WebDriver version 134.0.6998.90 selected
[2025-03-21T16:40:45.658+0000] {logger.py:11} INFO - Modern chrome version https://storage.googleapis.com/chrome-for-testing-public/134.0.6998.90/linux64/chromedriver-linux64.zip
[2025-03-21T16:40:45.658+0000] {logger.py:11} INFO - About to download new driver from https://storage.googleapis.com/chrome-for-testing-public/134.0.6998.90/linux64/chromedriver-linux64.zip
[2025-03-21T16:40:48.090+0000] {logger.py:11} INFO - Driver downloading response is 200
[2025-03-21T16:41:19.858+0000] {logger.py:11} INFO - Get LATEST chromedriver version for google-chrome
[2025-03-21T16:41:20.479+0000] {logger.py:11} INFO - Driver has been saved in cache [/home/nord/.wdm/drivers/chromedriver/linux64/134.0.6998.90]
[2025-03-21T16:41:54.090+0000] {local_task_job_runner.py:302} WARNING - State of this instance has been externally set to failed. Terminating instance.
[2025-03-21T16:41:54.099+0000] {process_utils.py:131} INFO - Sending 15 to group 4541. PIDs of all processes in the group: [5382, 5388, 4541]
[2025-03-21T16:41:54.100+0000] {process_utils.py:86} INFO - Sending the signal 15 to group 4541
[2025-03-21T16:41:54.101+0000] {taskinstance.py:2450} ERROR - Received SIGTERM. Terminating subprocesses.
[2025-03-21T16:41:54.102+0000] {logging_mixin.py:188} INFO - Erreur lors du scrolling : Task received SIGTERM signal
[2025-03-21T16:41:54.104+0000] {connectionpool.py:824} WARNING - Retrying (Retry(total=2, connect=None, read=None, redirect=None, status=None)) after connection broken by 'ProtocolError('Connection aborted.', ConnectionResetError(104, 'Connection reset by peer'))': /session/cb8c93777540a6a94baf257befd5db5c/source
[2025-03-21T16:41:54.106+0000] {connectionpool.py:824} WARNING - Retrying (Retry(total=1, connect=None, read=None, redirect=None, status=None)) after connection broken by 'NewConnectionError('<urllib3.connection.HTTPConnection object at 0x7f46b4fa9670>: Failed to establish a new connection: [Errno 111] Connection refused')': /session/cb8c93777540a6a94baf257befd5db5c/source
[2025-03-21T16:41:54.108+0000] {connectionpool.py:824} WARNING - Retrying (Retry(total=0, connect=None, read=None, redirect=None, status=None)) after connection broken by 'NewConnectionError('<urllib3.connection.HTTPConnection object at 0x7f46b4fa9ca0>: Failed to establish a new connection: [Errno 111] Connection refused')': /session/cb8c93777540a6a94baf257befd5db5c/source
[2025-03-21T16:41:54.114+0000] {connectionpool.py:824} WARNING - Retrying (Retry(total=2, connect=None, read=None, redirect=None, status=None)) after connection broken by 'NewConnectionError('<urllib3.connection.HTTPConnection object at 0x7f46b4f6a970>: Failed to establish a new connection: [Errno 111] Connection refused')': /session/cb8c93777540a6a94baf257befd5db5c
[2025-03-21T16:41:54.116+0000] {connectionpool.py:824} WARNING - Retrying (Retry(total=1, connect=None, read=None, redirect=None, status=None)) after connection broken by 'NewConnectionError('<urllib3.connection.HTTPConnection object at 0x7f46b4f6a880>: Failed to establish a new connection: [Errno 111] Connection refused')': /session/cb8c93777540a6a94baf257befd5db5c
[2025-03-21T16:41:54.117+0000] {connectionpool.py:824} WARNING - Retrying (Retry(total=0, connect=None, read=None, redirect=None, status=None)) after connection broken by 'NewConnectionError('<urllib3.connection.HTTPConnection object at 0x7f46b4f6a9d0>: Failed to establish a new connection: [Errno 111] Connection refused')': /session/cb8c93777540a6a94baf257befd5db5c
[2025-03-21T16:41:54.160+0000] {process_utils.py:79} INFO - Process psutil.Process(pid=5382, status='terminated', started='16:41:19') (5382) terminated with exit code None
[2025-03-21T16:41:54.162+0000] {process_utils.py:79} INFO - Process psutil.Process(pid=5388, status='terminated', started='16:41:19') (5388) terminated with exit code None
[2025-03-21T16:41:54.140+0000] {taskinstance.py:2698} ERROR - Task failed with exception
Traceback (most recent call last):
  File "/home/nord/venv/lib/python3.8/site-packages/urllib3/connection.py", line 174, in _new_conn
    conn = connection.create_connection(
  File "/home/nord/venv/lib/python3.8/site-packages/urllib3/util/connection.py", line 95, in create_connection
    raise err
  File "/home/nord/venv/lib/python3.8/site-packages/urllib3/util/connection.py", line 85, in create_connection
    sock.connect(sa)
ConnectionRefusedError: [Errno 111] Connection refused

During handling of the above exception, another exception occurred:

Traceback (most recent call last):
  File "/home/nord/venv/lib/python3.8/site-packages/urllib3/connectionpool.py", line 715, in urlopen
    httplib_response = self._make_request(
  File "/home/nord/venv/lib/python3.8/site-packages/urllib3/connectionpool.py", line 416, in _make_request
    conn.request(method, url, **httplib_request_kw)
  File "/home/nord/venv/lib/python3.8/site-packages/urllib3/connection.py", line 244, in request
    super(HTTPConnection, self).request(method, url, body=body, headers=headers)
  File "/usr/lib/python3.8/http/client.py", line 1256, in request
    self._send_request(method, url, body, headers, encode_chunked)
  File "/usr/lib/python3.8/http/client.py", line 1302, in _send_request
    self.endheaders(body, encode_chunked=encode_chunked)
  File "/usr/lib/python3.8/http/client.py", line 1251, in endheaders
    self._send_output(message_body, encode_chunked=encode_chunked)
  File "/usr/lib/python3.8/http/client.py", line 1011, in _send_output
    self.send(msg)
  File "/usr/lib/python3.8/http/client.py", line 951, in send
    self.connect()
  File "/home/nord/venv/lib/python3.8/site-packages/urllib3/connection.py", line 205, in connect
    conn = self._new_conn()
  File "/home/nord/venv/lib/python3.8/site-packages/urllib3/connection.py", line 186, in _new_conn
    raise NewConnectionError(
urllib3.exceptions.NewConnectionError: <urllib3.connection.HTTPConnection object at 0x7f46b4f6a040>: Failed to establish a new connection: [Errno 111] Connection refused

During handling of the above exception, another exception occurred:

Traceback (most recent call last):
  File "/home/nord/venv/lib/python3.8/site-packages/airflow/models/taskinstance.py", line 433, in _execute_task
    result = execute_callable(context=context, **execute_callable_kwargs)
  File "/home/nord/venv/lib/python3.8/site-packages/airflow/operators/python.py", line 199, in execute
    return_value = self.execute_callable()
  File "/home/nord/venv/lib/python3.8/site-packages/airflow/operators/python.py", line 216, in execute_callable
    return self.python_callable(*self.op_args, **self.op_kwargs)
  File "/home/nord/airflow/dags/google_map_dag_etl.py", line 33, in <lambda>
    python_callable=lambda: __import__('main_scraping_script').main()
  File "/home/nord/airflow/dags/main_scraping_script.py", line 155, in main
    all_data = extract_data(driver, banques)
  File "/home/nord/airflow/dags/main_scraping_script.py", line 127, in extract_data
    bank_data = extract_agency_data(driver, banque, url)
  File "/home/nord/airflow/dags/main_scraping_script.py", line 66, in extract_agency_data
    agencies_links = collect_agency_links(driver)
  File "/home/nord/airflow/dags/main_scraping_script.py", line 46, in collect_agency_links
    soup = BeautifulSoup(driver.page_source, 'html.parser')
  File "/home/nord/venv/lib/python3.8/site-packages/selenium/webdriver/remote/webdriver.py", line 485, in page_source
    return self.execute(Command.GET_PAGE_SOURCE)["value"]
  File "/home/nord/venv/lib/python3.8/site-packages/selenium/webdriver/remote/webdriver.py", line 382, in execute
    response = self.command_executor.execute(driver_command, params)
  File "/home/nord/venv/lib/python3.8/site-packages/selenium/webdriver/remote/remote_connection.py", line 404, in execute
    return self._request(command_info[0], url, body=data)
  File "/home/nord/venv/lib/python3.8/site-packages/selenium/webdriver/remote/remote_connection.py", line 428, in _request
    response = self._conn.request(method, url, body=body, headers=headers, timeout=self._client_config.timeout)
  File "/home/nord/venv/lib/python3.8/site-packages/urllib3/request.py", line 77, in request
    return self.request_encode_url(
  File "/home/nord/venv/lib/python3.8/site-packages/urllib3/request.py", line 99, in request_encode_url
    return self.urlopen(method, url, **extra_kw)
  File "/home/nord/venv/lib/python3.8/site-packages/urllib3/poolmanager.py", line 376, in urlopen
    response = conn.urlopen(method, u.request_uri, **kw)
  File "/home/nord/venv/lib/python3.8/site-packages/urllib3/connectionpool.py", line 827, in urlopen
    return self.urlopen(
  File "/home/nord/venv/lib/python3.8/site-packages/urllib3/connectionpool.py", line 827, in urlopen
    return self.urlopen(
  File "/home/nord/venv/lib/python3.8/site-packages/urllib3/connectionpool.py", line 827, in urlopen
    return self.urlopen(
  File "/home/nord/venv/lib/python3.8/site-packages/urllib3/connectionpool.py", line 799, in urlopen
    retries = retries.increment(
  File "/home/nord/venv/lib/python3.8/site-packages/urllib3/util/retry.py", line 592, in increment
    raise MaxRetryError(_pool, url, error or ResponseError(cause))
urllib3.exceptions.MaxRetryError: HTTPConnectionPool(host='localhost', port=39303): Max retries exceeded with url: /session/cb8c93777540a6a94baf257befd5db5c/source (Caused by NewConnectionError('<urllib3.connection.HTTPConnection object at 0x7f46b4f6a040>: Failed to establish a new connection: [Errno 111] Connection refused'))
[2025-03-21T16:41:54.206+0000] {taskinstance.py:1138} INFO - Marking task as FAILED. dag_id=Google_map, task_id=extract_data_task, execution_date=20250321T164009, start_date=20250321T164015, end_date=20250321T164154
[2025-03-21T16:41:54.244+0000] {standard_task_runner.py:107} ERROR - Failed to execute job 274 for task extract_data_task (HTTPConnectionPool(host='localhost', port=39303): Max retries exceeded with url: /session/cb8c93777540a6a94baf257befd5db5c/source (Caused by NewConnectionError('<urllib3.connection.HTTPConnection object at 0x7f46b4f6a040>: Failed to establish a new connection: [Errno 111] Connection refused')); 4541)
[2025-03-21T16:41:54.337+0000] {process_utils.py:79} INFO - Process psutil.Process(pid=4541, status='terminated', exitcode=1, started='16:40:15') (4541) terminated with exit code 1
