[2025-03-20T22:09:16.967+0000] {taskinstance.py:1956} INFO - Dependencies all met for dep_context=non-requeueable deps ti=<TaskInstance: Google_map.extract_data_task manual__2025-03-20T22:02:38.687555+00:00 [queued]>
[2025-03-20T22:09:16.997+0000] {taskinstance.py:1956} INFO - Dependencies all met for dep_context=requeueable deps ti=<TaskInstance: Google_map.extract_data_task manual__2025-03-20T22:02:38.687555+00:00 [queued]>
[2025-03-20T22:09:16.998+0000] {taskinstance.py:2170} INFO - Starting attempt 2 of 2
[2025-03-20T22:09:17.037+0000] {taskinstance.py:2191} INFO - Executing <Task(PythonOperator): extract_data_task> on 2025-03-20 22:02:38.687555+00:00
[2025-03-20T22:09:17.048+0000] {standard_task_runner.py:60} INFO - Started process 6771 to run task
[2025-03-20T22:09:17.058+0000] {standard_task_runner.py:87} INFO - Running: ['airflow', 'tasks', 'run', 'Google_map', 'extract_data_task', 'manual__2025-03-20T22:02:38.687555+00:00', '--job-id', '240', '--raw', '--subdir', 'DAGS_FOLDER/google_map_dag_etl.py', '--cfg-path', '/tmp/tmpav9rt7om']
[2025-03-20T22:09:17.064+0000] {standard_task_runner.py:88} INFO - Job 240: Subtask extract_data_task
[2025-03-20T22:09:17.253+0000] {task_command.py:423} INFO - Running <TaskInstance: Google_map.extract_data_task manual__2025-03-20T22:02:38.687555+00:00 [running]> on host DESKTOP-AVAHALM.
[2025-03-20T22:09:17.590+0000] {taskinstance.py:2480} INFO - Exporting env vars: AIRFLOW_CTX_DAG_OWNER='master_m2si' AIRFLOW_CTX_DAG_ID='Google_map' AIRFLOW_CTX_TASK_ID='extract_data_task' AIRFLOW_CTX_EXECUTION_DATE='2025-03-20T22:02:38.687555+00:00' AIRFLOW_CTX_TRY_NUMBER='2' AIRFLOW_CTX_DAG_RUN_ID='manual__2025-03-20T22:02:38.687555+00:00'
[2025-03-20T22:09:18.400+0000] {logger.py:11} INFO - ====== WebDriver manager ======
[2025-03-20T22:09:19.167+0000] {logger.py:11} INFO - Get LATEST chromedriver version for google-chrome
[2025-03-20T22:09:29.199+0000] {taskinstance.py:2698} ERROR - Task failed with exception
Traceback (most recent call last):
  File "/home/nord/venv/lib/python3.8/site-packages/urllib3/connection.py", line 174, in _new_conn
    conn = connection.create_connection(
  File "/home/nord/venv/lib/python3.8/site-packages/urllib3/util/connection.py", line 72, in create_connection
    for res in socket.getaddrinfo(host, port, family, socket.SOCK_STREAM):
  File "/usr/lib/python3.8/socket.py", line 918, in getaddrinfo
    for res in _socket.getaddrinfo(host, port, family, type, proto, flags):
socket.gaierror: [Errno -3] Temporary failure in name resolution

During handling of the above exception, another exception occurred:

Traceback (most recent call last):
  File "/home/nord/venv/lib/python3.8/site-packages/urllib3/connectionpool.py", line 715, in urlopen
    httplib_response = self._make_request(
  File "/home/nord/venv/lib/python3.8/site-packages/urllib3/connectionpool.py", line 404, in _make_request
    self._validate_conn(conn)
  File "/home/nord/venv/lib/python3.8/site-packages/urllib3/connectionpool.py", line 1058, in _validate_conn
    conn.connect()
  File "/home/nord/venv/lib/python3.8/site-packages/urllib3/connection.py", line 363, in connect
    self.sock = conn = self._new_conn()
  File "/home/nord/venv/lib/python3.8/site-packages/urllib3/connection.py", line 186, in _new_conn
    raise NewConnectionError(
urllib3.exceptions.NewConnectionError: <urllib3.connection.HTTPSConnection object at 0x7efc61558df0>: Failed to establish a new connection: [Errno -3] Temporary failure in name resolution

During handling of the above exception, another exception occurred:

Traceback (most recent call last):
  File "/home/nord/venv/lib/python3.8/site-packages/requests/adapters.py", line 486, in send
    resp = conn.urlopen(
  File "/home/nord/venv/lib/python3.8/site-packages/urllib3/connectionpool.py", line 799, in urlopen
    retries = retries.increment(
  File "/home/nord/venv/lib/python3.8/site-packages/urllib3/util/retry.py", line 592, in increment
    raise MaxRetryError(_pool, url, error or ResponseError(cause))
urllib3.exceptions.MaxRetryError: HTTPSConnectionPool(host='googlechromelabs.github.io', port=443): Max retries exceeded with url: /chrome-for-testing/latest-patch-versions-per-build.json (Caused by NewConnectionError('<urllib3.connection.HTTPSConnection object at 0x7efc61558df0>: Failed to establish a new connection: [Errno -3] Temporary failure in name resolution'))

During handling of the above exception, another exception occurred:

Traceback (most recent call last):
  File "/home/nord/venv/lib/python3.8/site-packages/webdriver_manager/core/http.py", line 32, in get
    resp = requests.get(
  File "/home/nord/venv/lib/python3.8/site-packages/requests/api.py", line 73, in get
    return request("get", url, params=params, **kwargs)
  File "/home/nord/venv/lib/python3.8/site-packages/requests/api.py", line 59, in request
    return session.request(method=method, url=url, **kwargs)
  File "/home/nord/venv/lib/python3.8/site-packages/requests/sessions.py", line 589, in request
    resp = self.send(prep, **send_kwargs)
  File "/home/nord/venv/lib/python3.8/site-packages/requests/sessions.py", line 703, in send
    r = adapter.send(request, **kwargs)
  File "/home/nord/venv/lib/python3.8/site-packages/requests/adapters.py", line 519, in send
    raise ConnectionError(e, request=request)
requests.exceptions.ConnectionError: HTTPSConnectionPool(host='googlechromelabs.github.io', port=443): Max retries exceeded with url: /chrome-for-testing/latest-patch-versions-per-build.json (Caused by NewConnectionError('<urllib3.connection.HTTPSConnection object at 0x7efc61558df0>: Failed to establish a new connection: [Errno -3] Temporary failure in name resolution'))

During handling of the above exception, another exception occurred:

Traceback (most recent call last):
  File "/home/nord/venv/lib/python3.8/site-packages/airflow/models/taskinstance.py", line 433, in _execute_task
    result = execute_callable(context=context, **execute_callable_kwargs)
  File "/home/nord/venv/lib/python3.8/site-packages/airflow/operators/python.py", line 199, in execute
    return_value = self.execute_callable()
  File "/home/nord/venv/lib/python3.8/site-packages/airflow/operators/python.py", line 216, in execute_callable
    return self.python_callable(*self.op_args, **self.op_kwargs)
  File "/home/nord/airflow/dags/google_map_dag_etl.py", line 33, in <lambda>
    python_callable=lambda: __import__('main_scraping_script').main()
  File "/home/nord/airflow/dags/main_scraping_script.py", line 132, in main
    driver = initialize_driver()
  File "/home/nord/airflow/dags/main_scraping_script.py", line 21, in initialize_driver
    service = Service(ChromeDriverManager().install())
  File "/home/nord/venv/lib/python3.8/site-packages/webdriver_manager/chrome.py", line 40, in install
    driver_path = self._get_driver_binary_path(self.driver)
  File "/home/nord/venv/lib/python3.8/site-packages/webdriver_manager/core/manager.py", line 35, in _get_driver_binary_path
    binary_path = self._cache_manager.find_driver(driver)
  File "/home/nord/venv/lib/python3.8/site-packages/webdriver_manager/core/driver_cache.py", line 107, in find_driver
    driver_version = self.get_cache_key_driver_version(driver)
  File "/home/nord/venv/lib/python3.8/site-packages/webdriver_manager/core/driver_cache.py", line 154, in get_cache_key_driver_version
    return driver.get_driver_version_to_download()
  File "/home/nord/venv/lib/python3.8/site-packages/webdriver_manager/core/driver.py", line 48, in get_driver_version_to_download
    return self.get_latest_release_version()
  File "/home/nord/venv/lib/python3.8/site-packages/webdriver_manager/drivers/chrome.py", line 59, in get_latest_release_version
    response = self._http_client.get(url)
  File "/home/nord/venv/lib/python3.8/site-packages/webdriver_manager/core/http.py", line 35, in get
    raise exceptions.ConnectionError(f"Could not reach host. Are you offline?")
requests.exceptions.ConnectionError: Could not reach host. Are you offline?
[2025-03-20T22:09:29.322+0000] {taskinstance.py:1138} INFO - Marking task as FAILED. dag_id=Google_map, task_id=extract_data_task, execution_date=20250320T220238, start_date=20250320T220916, end_date=20250320T220929
[2025-03-20T22:09:29.443+0000] {standard_task_runner.py:107} ERROR - Failed to execute job 240 for task extract_data_task (Could not reach host. Are you offline?; 6771)
[2025-03-20T22:09:29.469+0000] {local_task_job_runner.py:234} INFO - Task exited with return code 1
[2025-03-20T22:09:29.554+0000] {taskinstance.py:3280} INFO - 0 downstream tasks scheduled from follow-on schedule check
