[2025-03-17T22:30:28.419+0000] {taskinstance.py:1956} INFO - Dependencies all met for dep_context=non-requeueable deps ti=<TaskInstance: Google_map.transform_data_phase_1_task manual__2025-03-17T22:29:46.221740+00:00 [queued]>
[2025-03-17T22:30:28.640+0000] {taskinstance.py:1956} INFO - Dependencies all met for dep_context=requeueable deps ti=<TaskInstance: Google_map.transform_data_phase_1_task manual__2025-03-17T22:29:46.221740+00:00 [queued]>
[2025-03-17T22:30:28.641+0000] {taskinstance.py:2170} INFO - Starting attempt 1 of 2
[2025-03-17T22:30:28.973+0000] {taskinstance.py:2191} INFO - Executing <Task(BashOperator): transform_data_phase_1_task> on 2025-03-17 22:29:46.221740+00:00
[2025-03-17T22:30:28.981+0000] {standard_task_runner.py:60} INFO - Started process 16009 to run task
[2025-03-17T22:30:29.022+0000] {standard_task_runner.py:87} INFO - Running: ['airflow', 'tasks', 'run', 'Google_map', 'transform_data_phase_1_task', 'manual__2025-03-17T22:29:46.221740+00:00', '--job-id', '201', '--raw', '--subdir', 'DAGS_FOLDER/google_map_dag_etl.py', '--cfg-path', '/tmp/tmpxowyt9q9']
[2025-03-17T22:30:29.026+0000] {standard_task_runner.py:88} INFO - Job 201: Subtask transform_data_phase_1_task
[2025-03-17T22:30:31.715+0000] {task_command.py:423} INFO - Running <TaskInstance: Google_map.transform_data_phase_1_task manual__2025-03-17T22:29:46.221740+00:00 [running]> on host DESKTOP-AVAHALM.
[2025-03-17T22:30:35.750+0000] {taskinstance.py:2480} INFO - Exporting env vars: AIRFLOW_CTX_DAG_OWNER='master_m2si' AIRFLOW_CTX_DAG_ID='Google_map' AIRFLOW_CTX_TASK_ID='transform_data_phase_1_task' AIRFLOW_CTX_EXECUTION_DATE='2025-03-17T22:29:46.221740+00:00' AIRFLOW_CTX_TRY_NUMBER='1' AIRFLOW_CTX_DAG_RUN_ID='manual__2025-03-17T22:29:46.221740+00:00'
[2025-03-17T22:30:35.756+0000] {subprocess.py:63} INFO - Tmp dir root location: /tmp
[2025-03-17T22:30:35.758+0000] {subprocess.py:75} INFO - Running command: ['/usr/bin/bash', '-c', 'cd ~/data_warehouse_project && dbt run --profiles-dir ~/.dbt --models cleaned_reviews']
[2025-03-17T22:30:35.799+0000] {subprocess.py:86} INFO - Output:
[2025-03-17T22:30:58.997+0000] {subprocess.py:93} INFO - [0m22:30:58  Running with dbt=1.9.0-b2
[2025-03-17T22:31:06.044+0000] {subprocess.py:93} INFO - [0m22:31:06  Registered adapter: postgres=1.8.2
[2025-03-17T22:31:09.809+0000] {subprocess.py:93} INFO - [0m22:31:09  [[33mWARNING[0m]: Configuration paths exist in your dbt_project.yml file which do not apply to any resources.
[2025-03-17T22:31:09.810+0000] {subprocess.py:93} INFO - There are 1 unused configuration paths:
[2025-03-17T22:31:09.810+0000] {subprocess.py:93} INFO - - models.data_warehouse_project.example
[2025-03-17T22:31:13.061+0000] {subprocess.py:93} INFO - [0m22:31:13  Found 6 models, 1 source, 424 macros
[2025-03-17T22:31:13.113+0000] {subprocess.py:93} INFO - [0m22:31:13
[2025-03-17T22:31:13.127+0000] {subprocess.py:93} INFO - [0m22:31:13  Concurrency: 4 threads (target='dev')
[2025-03-17T22:31:13.131+0000] {subprocess.py:93} INFO - [0m22:31:13
[2025-03-17T22:31:16.068+0000] {subprocess.py:93} INFO - [0m22:31:16  1 of 1 START sql table model public.cleaned_reviews ............................ [RUN]
[2025-03-17T22:31:18.006+0000] {subprocess.py:93} INFO - [0m22:31:18  1 of 1 ERROR creating sql table model public.cleaned_reviews ................... [[31mERROR[0m in 1.93s]
[2025-03-17T22:31:18.365+0000] {subprocess.py:93} INFO - [0m22:31:18
[2025-03-17T22:31:18.378+0000] {subprocess.py:93} INFO - [0m22:31:18  Finished running 1 table model in 0 hours 0 minutes and 5.23 seconds (5.23s).
[2025-03-17T22:31:19.036+0000] {subprocess.py:93} INFO - [0m22:31:19
[2025-03-17T22:31:19.051+0000] {subprocess.py:93} INFO - [0m22:31:19  [31mCompleted with 1 error, 0 partial successs, and 0 warnings:[0m
[2025-03-17T22:31:19.054+0000] {subprocess.py:93} INFO - [0m22:31:19
[2025-03-17T22:31:19.071+0000] {subprocess.py:93} INFO - [0m22:31:19    Database Error in model cleaned_reviews (models/cleaned_reviews.sql)
[2025-03-17T22:31:19.072+0000] {subprocess.py:93} INFO -   relation "cleaned_reviews__dbt_backup" already exists
[2025-03-17T22:31:19.073+0000] {subprocess.py:93} INFO -   compiled code at target/run/data_warehouse_project/models/cleaned_reviews.sql
[2025-03-17T22:31:19.075+0000] {subprocess.py:93} INFO - [0m22:31:19
[2025-03-17T22:31:19.078+0000] {subprocess.py:93} INFO - [0m22:31:19  Done. PASS=0 WARN=0 ERROR=1 SKIP=0 TOTAL=1
[2025-03-17T22:31:23.540+0000] {subprocess.py:97} INFO - Command exited with return code 1
[2025-03-17T22:31:24.381+0000] {taskinstance.py:2698} ERROR - Task failed with exception
Traceback (most recent call last):
  File "/home/nord/venv/lib/python3.8/site-packages/airflow/models/taskinstance.py", line 433, in _execute_task
    result = execute_callable(context=context, **execute_callable_kwargs)
  File "/home/nord/venv/lib/python3.8/site-packages/airflow/operators/bash.py", line 212, in execute
    raise AirflowException(
airflow.exceptions.AirflowException: Bash command failed. The command returned a non-zero exit code 1.
[2025-03-17T22:31:24.473+0000] {taskinstance.py:1138} INFO - Marking task as UP_FOR_RETRY. dag_id=Google_map, task_id=transform_data_phase_1_task, execution_date=20250317T222946, start_date=20250317T223028, end_date=20250317T223124
[2025-03-17T22:31:25.421+0000] {standard_task_runner.py:107} ERROR - Failed to execute job 201 for task transform_data_phase_1_task (Bash command failed. The command returned a non-zero exit code 1.; 16009)
[2025-03-17T22:31:25.480+0000] {local_task_job_runner.py:234} INFO - Task exited with return code 1
[2025-03-17T22:31:27.179+0000] {taskinstance.py:3280} INFO - 0 downstream tasks scheduled from follow-on schedule check
