[2025-03-15T15:55:10.106+0000] {taskinstance.py:1956} INFO - Dependencies all met for dep_context=non-requeueable deps ti=<TaskInstance: Google_map.extract_data_task manual__2025-03-15T15:55:06.054403+00:00 [queued]>
[2025-03-15T15:55:10.130+0000] {taskinstance.py:1956} INFO - Dependencies all met for dep_context=requeueable deps ti=<TaskInstance: Google_map.extract_data_task manual__2025-03-15T15:55:06.054403+00:00 [queued]>
[2025-03-15T15:55:10.130+0000] {taskinstance.py:2170} INFO - Starting attempt 1 of 2
[2025-03-15T15:55:10.177+0000] {taskinstance.py:2191} INFO - Executing <Task(PythonOperator): extract_data_task> on 2025-03-15 15:55:06.054403+00:00
[2025-03-15T15:55:10.202+0000] {standard_task_runner.py:60} INFO - Started process 16676 to run task
[2025-03-15T15:55:10.208+0000] {standard_task_runner.py:87} INFO - Running: ['airflow', 'tasks', 'run', 'Google_map', 'extract_data_task', 'manual__2025-03-15T15:55:06.054403+00:00', '--job-id', '69', '--raw', '--subdir', 'DAGS_FOLDER/google_map_dag_etl.py', '--cfg-path', '/tmp/tmphfe8uqo_']
[2025-03-15T15:55:10.222+0000] {standard_task_runner.py:88} INFO - Job 69: Subtask extract_data_task
[2025-03-15T15:55:10.474+0000] {task_command.py:423} INFO - Running <TaskInstance: Google_map.extract_data_task manual__2025-03-15T15:55:06.054403+00:00 [running]> on host DESKTOP-AVAHALM.
[2025-03-15T15:55:10.749+0000] {taskinstance.py:2480} INFO - Exporting env vars: AIRFLOW_CTX_DAG_OWNER='master_m2si' AIRFLOW_CTX_DAG_ID='Google_map' AIRFLOW_CTX_TASK_ID='extract_data_task' AIRFLOW_CTX_EXECUTION_DATE='2025-03-15T15:55:06.054403+00:00' AIRFLOW_CTX_TRY_NUMBER='1' AIRFLOW_CTX_DAG_RUN_ID='manual__2025-03-15T15:55:06.054403+00:00'
[2025-03-15T15:55:11.326+0000] {taskinstance.py:2698} ERROR - Task failed with exception
Traceback (most recent call last):
  File "/home/nord/venv/lib/python3.8/site-packages/airflow/models/taskinstance.py", line 433, in _execute_task
    result = execute_callable(context=context, **execute_callable_kwargs)
  File "/home/nord/venv/lib/python3.8/site-packages/airflow/operators/python.py", line 199, in execute
    return_value = self.execute_callable()
  File "/home/nord/venv/lib/python3.8/site-packages/airflow/operators/python.py", line 216, in execute_callable
    return self.python_callable(*self.op_args, **self.op_kwargs)
  File "/home/nord/airflow/dags/google_map_dag_etl.py", line 120, in <lambda>
    python_callable=lambda: __import__('mini_scraping').main()
  File "/home/nord/airflow/dags/mini_scraping.py", line 7, in <module>
    from selenium import webdriver
ModuleNotFoundError: No module named 'selenium'
[2025-03-15T15:55:11.413+0000] {taskinstance.py:1138} INFO - Marking task as UP_FOR_RETRY. dag_id=Google_map, task_id=extract_data_task, execution_date=20250315T155506, start_date=20250315T155510, end_date=20250315T155511
[2025-03-15T15:55:11.513+0000] {standard_task_runner.py:107} ERROR - Failed to execute job 69 for task extract_data_task (No module named 'selenium'; 16676)
[2025-03-15T15:55:11.555+0000] {local_task_job_runner.py:234} INFO - Task exited with return code 1
[2025-03-15T15:55:11.639+0000] {taskinstance.py:3280} INFO - 0 downstream tasks scheduled from follow-on schedule check
