[2025-03-16T15:43:08.474+0000] {taskinstance.py:1956} INFO - Dependencies all met for dep_context=non-requeueable deps ti=<TaskInstance: Google_map.transform_data_phase_1_task manual__2025-03-16T15:37:50.251721+00:00 [queued]>
[2025-03-16T15:43:08.490+0000] {taskinstance.py:1956} INFO - Dependencies all met for dep_context=requeueable deps ti=<TaskInstance: Google_map.transform_data_phase_1_task manual__2025-03-16T15:37:50.251721+00:00 [queued]>
[2025-03-16T15:43:08.491+0000] {taskinstance.py:2170} INFO - Starting attempt 2 of 2
[2025-03-16T15:43:08.527+0000] {taskinstance.py:2191} INFO - Executing <Task(BashOperator): transform_data_phase_1_task> on 2025-03-16 15:37:50.251721+00:00
[2025-03-16T15:43:08.541+0000] {standard_task_runner.py:60} INFO - Started process 69431 to run task
[2025-03-16T15:43:08.550+0000] {standard_task_runner.py:87} INFO - Running: ['airflow', 'tasks', 'run', 'Google_map', 'transform_data_phase_1_task', 'manual__2025-03-16T15:37:50.251721+00:00', '--job-id', '120', '--raw', '--subdir', 'DAGS_FOLDER/google_map_dag_etl.py', '--cfg-path', '/tmp/tmp5ea1tc98']
[2025-03-16T15:43:08.556+0000] {standard_task_runner.py:88} INFO - Job 120: Subtask transform_data_phase_1_task
[2025-03-16T15:43:08.709+0000] {task_command.py:423} INFO - Running <TaskInstance: Google_map.transform_data_phase_1_task manual__2025-03-16T15:37:50.251721+00:00 [running]> on host DESKTOP-AVAHALM.
[2025-03-16T15:43:08.911+0000] {taskinstance.py:2480} INFO - Exporting env vars: AIRFLOW_CTX_DAG_OWNER='master_m2si' AIRFLOW_CTX_DAG_ID='Google_map' AIRFLOW_CTX_TASK_ID='transform_data_phase_1_task' AIRFLOW_CTX_EXECUTION_DATE='2025-03-16T15:37:50.251721+00:00' AIRFLOW_CTX_TRY_NUMBER='2' AIRFLOW_CTX_DAG_RUN_ID='manual__2025-03-16T15:37:50.251721+00:00'
[2025-03-16T15:43:08.915+0000] {subprocess.py:63} INFO - Tmp dir root location: /tmp
[2025-03-16T15:43:08.916+0000] {subprocess.py:75} INFO - Running command: ['/usr/bin/bash', '-c', 'cd ~/data_warehouse_project && dbt run --profiles-dir ~/.dbt/profiles.yml --models cleaned_review']
[2025-03-16T15:43:08.930+0000] {subprocess.py:86} INFO - Output:
[2025-03-16T15:43:12.574+0000] {subprocess.py:93} INFO - [0m15:43:12  Running with dbt=1.9.0-b2
[2025-03-16T15:43:12.592+0000] {subprocess.py:93} INFO - [0m15:43:12  Encountered an error:
[2025-03-16T15:43:12.593+0000] {subprocess.py:93} INFO - Runtime Error
[2025-03-16T15:43:12.593+0000] {subprocess.py:93} INFO -   Could not find profile named 'data_warehouse_project'
[2025-03-16T15:43:13.867+0000] {subprocess.py:97} INFO - Command exited with return code 2
[2025-03-16T15:43:13.892+0000] {taskinstance.py:2698} ERROR - Task failed with exception
Traceback (most recent call last):
  File "/home/nord/venv/lib/python3.8/site-packages/airflow/models/taskinstance.py", line 433, in _execute_task
    result = execute_callable(context=context, **execute_callable_kwargs)
  File "/home/nord/venv/lib/python3.8/site-packages/airflow/operators/bash.py", line 212, in execute
    raise AirflowException(
airflow.exceptions.AirflowException: Bash command failed. The command returned a non-zero exit code 2.
[2025-03-16T15:43:13.898+0000] {taskinstance.py:1138} INFO - Marking task as FAILED. dag_id=Google_map, task_id=transform_data_phase_1_task, execution_date=20250316T153750, start_date=20250316T154308, end_date=20250316T154313
[2025-03-16T15:43:13.923+0000] {standard_task_runner.py:107} ERROR - Failed to execute job 120 for task transform_data_phase_1_task (Bash command failed. The command returned a non-zero exit code 2.; 69431)
[2025-03-16T15:43:13.957+0000] {local_task_job_runner.py:234} INFO - Task exited with return code 1
[2025-03-16T15:43:14.020+0000] {taskinstance.py:3280} INFO - 0 downstream tasks scheduled from follow-on schedule check
